Workbook
Name Gauntlet: '_OptionsCrafter'!$K$151:$K$155
Name Colossal_Sword: '_OptionsCrafter'!$Q$151:$Q$161
Name Great_Axe: '_OptionsCrafter'!$P$151:$P$158
Name Straight_Sword: '_OptionsCrafter'!$I$151:$I$162
Name Spear: '_OptionsCrafter'!$O$151:$O$160
Name Dagger: '_OptionsCrafter'!$H$151:$H$160
Name Mace: '_OptionsCrafter'!$J$151:$J$157
Name Axe: '_OptionsCrafter'!$L$151:$L$155
Name Katana: '_OptionsCrafter'!$M$151:$M$156
Name Great_Sword: '_OptionsCrafter'!$N$151:$N$155

Sheet DPS Calculator
A1: LittleTimmy's "The Forge" Calculator | N1: Dagger | O1: Straight Sword | P1: Mace | Q1: Gauntlet | R1: Axe | S1: Katana | T1: Great Sword | U1: Spear | V1: Great Axe | W1: Colossal Sword
A2: Yellow = editable input | Green = calculated | Grey = locked (fixed game initial value) | N2: Dagger | O2: Falchion | P2: Mace | Q2: Ironhand | R2: Axe | S2: Uchigatana | T2: Crusader Sword | U2: Spear | V2: Double Battle Axe | W2: Great Sword
A3: YOU WILL NOT BE ABLE TO EDIT THIS SHEET HERE. YOU NEED TO CREATE YOUR OWN COPY BY GOING TO "FILE" > "MAKE A COPY" TO BE ABLE TO EDIT YOURSELF | N3: Falchion Knife | O3: Gladius | P3: Spiked Mace | Q3: Boxing Glove | R3: Battleaxe | S3: Tachi | T3: Long Sword | U3: Trident | V3: Scythe | W3: Hammer
B4: WEAPON CRAFTER | N4: Gladius Dagger | O4: Cutlass | P4: Winged Mace | Q4: Relevator | R4: Curved Handle Axe | S4: Straight Edge Katana | T4: Dark Knight Greatsword | U4: Angelic Spear | V4: Greater Battle Axe | W4: Skull Crusher
B5: Category | C5: Type | D5: Amount | E5: Multiplier | N5: Hook | O5: Rapier | P5: Hammerhead Mace | Q5: Savage Claws | R5: Spade Armed Axe | S5: Washimaru | T5: Anchored Greatsword | U5: Demonic Spear | V5: Wyvern Axe | W5: Dragon Slayer
B6: Ore 1 | C6: Ancienite | D6: 10 | E6: =IF(C6="Select Ore",1,IFERROR(VALUE(SUBSTITUTE(VLOOKUP(C6,'_OptionsCrafter'!$A$55:$C$195,3,0),"x","")),1)) -> 13.33 | F6: =VLOOKUP(C6, '_OptionsCrafter'!$A$55:$G$195, 7, FALSE) | G6: =VLOOKUP(D6, '_OptionsCrafter'!$A$55:$G$195, 7, FALSE) -> #N/A | I6: =IF(C6="Select Ore",0,IF(ISNUMBER(SEARCH("eapon",IFERROR(VLOOKUP(C6,'_OptionsCrafter'!$A$55:$F$195,2,0),""))),1,0)) -> 0 | J6: =IF(SUM($D$6:$D$9)=0,0,IF(ISNUMBER(D6),D6/SUM($D$6:$D$9),0)) -> 0.5 | K6: =IF(OR(I6=0,J6<0.1),0,MIN(MAX((J6-0.1)*4.5+0.1,0.1),1)) -> 0 | L6: =IF(K6=0,"",IF(J6>=0.3,IFERROR(VLOOKUP(C6,'_OptionsCrafter'!$A$55:$F$195,5,0),""),"["&TEXT(K6*100,"0.0")&"% power] "&IFERROR(VLOOKUP(C6,'_OptionsCrafter'!$A$55:$F$195,4,0),""))) | N6: Cultist Dagger | O6: Chaos | P6: Grave Maker | Q6: DKG | R6: Ornate short axe | S6: Kurokiba-gatana | T6: Zweihander | U6: Knight Spear | V6: Reaper | W6: Comically Large Spoon
B7: Ore 2 | C7: Aetherit | D7: 10 | E7: =IF(C7="Select Ore",1,IFERROR(VALUE(SUBSTITUTE(VLOOKUP(C7,'_OptionsCrafter'!$A$55:$C$195,3,0),"x","")),1)) -> 2.55 | F7: =VLOOKUP(C7, '_OptionsCrafter'!$A$55:$G$195, 7, FALSE) | G7: =VLOOKUP(D7, '_OptionsCrafter'!$A$55:$G$195, 7, FALSE) -> #N/A | I7: =IF(C7="Select Ore",0,IF(ISNUMBER(SEARCH("eapon",IFERROR(VLOOKUP(C7,'_OptionsCrafter'!$A$55:$F$195,2,0),""))),1,0)) -> 0 | J7: =IF(SUM($D$6:$D$9)=0,0,IF(ISNUMBER(D7),D7/SUM($D$6:$D$9),0)) -> 0.5 | K7: =IF(OR(I7=0,J7<0.1),0,MIN(MAX((J7-0.1)*4.5+0.1,0.1),1)) -> 0 | L7: =IF(K7=0,"",IF(J7>=0.3,IFERROR(VLOOKUP(C7,'_OptionsCrafter'!$A$55:$F$195,5,0),""),"["&TEXT(K7*100,"0.0")&"% power] "&IFERROR(VLOOKUP(C7,'_OptionsCrafter'!$A$55:$F$195,4,0),""))) | N7: Shark's Fang | O7: Hell Slayer | P7: Kanabo | S7: Juto Katana | U7: Compass Spear | V7: Executioner's Greataxe | W7: Excalibur
B8: Ore 3 | C8: Select Ore | D8: 0 | E8: =IF(C8="Select Ore",1,IFERROR(VALUE(SUBSTITUTE(VLOOKUP(C8,'_OptionsCrafter'!$A$55:$C$195,3,0),"x","")),1)) -> 1 | F8: =VLOOKUP(C8, '_OptionsCrafter'!$A$55:$G$195, 7, FALSE) -> #N/A | G8: =VLOOKUP(D8, '_OptionsCrafter'!$A$55:$G$195, 7, FALSE) -> #N/A | I8: =IF(C8="Select Ore",0,IF(ISNUMBER(SEARCH("eapon",IFERROR(VLOOKUP(C8,'_OptionsCrafter'!$A$55:$F$195,2,0),""))),1,0)) -> 0 | J8: =IF(SUM($D$6:$D$9)=0,0,IF(ISNUMBER(D8),D8/SUM($D$6:$D$9),0)) -> 0 | K8: =IF(OR(I8=0,J8<0.1),0,MIN(MAX((J8-0.1)*4.5+0.1,0.1),1)) -> 0 | L8: =IF(K8=0,"",IF(J8>=0.3,IFERROR(VLOOKUP(C8,'_OptionsCrafter'!$A$55:$F$195,5,0),""),"["&TEXT(K8*100,"0.0")&"% power] "&IFERROR(VLOOKUP(C8,'_OptionsCrafter'!$A$55:$F$195,4,0),""))) | N8: Curved Dagger | O8: Candy Cane | P8: Tetsubo | U8: Shakujo | V8: Anchored Straight Blade | W8: Colossal Terrorblade
B9: Ore 4 | C9: Select Ore | D9: 0 | E9: =IF(C9="Select Ore",1,IFERROR(VALUE(SUBSTITUTE(VLOOKUP(C9,'_OptionsCrafter'!$A$55:$C$195,3,0),"x","")),1)) -> 1 | F9: =VLOOKUP(C9, '_OptionsCrafter'!$A$55:$G$195, 7, FALSE) -> #N/A | G9: =VLOOKUP(D9, '_OptionsCrafter'!$A$55:$G$195, 7, FALSE) -> #N/A | I9: =IF(C9="Select Ore",0,IF(ISNUMBER(SEARCH("eapon",IFERROR(VLOOKUP(C9,'_OptionsCrafter'!$A$55:$F$195,2,0),""))),1,0)) -> 0 | J9: =IF(SUM($D$6:$D$9)=0,0,IF(ISNUMBER(D9),D9/SUM($D$6:$D$9),0)) -> 0 | K9: =IF(OR(I9=0,J9<0.1),0,MIN(MAX((J9-0.1)*4.5+0.1,0.1),1)) -> 0 | L9: =IF(K9=0,"",IF(J9>=0.3,IFERROR(VLOOKUP(C9,'_OptionsCrafter'!$A$55:$F$195,5,0),""),"["&TEXT(K9*100,"0.0")&"% power] "&IFERROR(VLOOKUP(C9,'_OptionsCrafter'!$A$55:$F$195,4,0),""))) | N9: Kunai | O9: Crystalized Broadsword | U9: Sodegarami | V9: Sun Great Axe | W9: Colossal Gemblade
B10: Total | D10: =SUM(D6+D7+D8+D9) -> 20 | E10: =IFERROR(SUMPRODUCT(D6:D9,E6:E9)/SUM(D6:D9),AVERAGE(E6:E9)) -> 7.94 | N10: Jitte | O10: Hook Blade | U10: Bo Staff | W10: Otsuchi
B11: ------------------------------------------------- | C11: Type | D11: Weapon | E11: Quality (%) | N11: Damascus Dagger | O11: Hachiwari | U11: Naginata | W11: Kinmon Kamagatana
B12: Weapon | C12: Spear | D12: Demonic Spear | E12: 100 | O12: Chokuto | W12: Sharktooth Odachi
B13: Enhancement Level (0-9) | C13: 0 | D13: Base DMG | E13: =A18 -> 142.92 | O13: Dragon Blade
B14: Active Traits | C14: =IFERROR(TEXTJOIN(" | ",TRUE, IF(L6="","",L6), IF(L7="","",L7), IF(L8="","",L8), IF(L9="","",L9)),"No active weapon traits")
B16: BASE WEAPON STATS
B17: Stat | C17: Value | D17: Formula | E17: Result
A18: =IFERROR(VLOOKUP(D12,'_Weapon'!$C$2:$E$80,3,0)*E10*(1+E12/100),1) -> 142.92 | B18: Weapon DMG | C18: =IFERROR(VLOOKUP(D12,'_Weapon'!$C$2:$E$80,3,0)*E10*SWITCH(C13,0,1,1,1.05,2,1.1,3,1.15,4,1.2,5,1.25,6,1.3,7,1.35,8,1.4,9,1.5,1)*(1+E12/100),1) -> 142.92 | D18: Hits per Second | E18: =1/C19 -> 1.2658228
B19: Base Attack Speed (seconds) | C19: =IFERROR(VLOOKUP(D12,'_Weapon'!$C$2:$E$80,2,0),1) -> 0.79 | D19: Avg DMG per Hit (with crit) | E19: =C18*(1+E44)*(MIN(C20+E45,1)*(C21+E46)+(1-MIN(C20+E45,1))) -> 142.92
B20: Base Crit Chance % | C20: 0 | D20: Effective Atk Speed (s) | E20: =C19/(1+E47) -> 0.79
B21: Base Crit Multiplier % | C21: 1.45 | D21: Effective Hits/sec | E21: =1/E20 -> 1.2658228
B22: Race | C22: Human | D22: Applied trait(s) | E22: {=IF(IFERROR(TEXTJOIN(", ",TRUE,IF(INDEX('_Options'!$F$2:$U$17,MATCH(C22,'_Options'!$E$2:$E$17,0),0)=TRUE,'_Options'!$F$1:$U$1,"")),"")="","N/A",IFERROR(TEXTJOIN(", ",TRUE,IF(INDEX('_Options'!$F$2:$U$17,MATCH(C22,'_Options'!$E$2:$E$17,0),0)=TRUE,'_Options'!$F$1:$U$1,"")),""))} -> N/A
B23: Weapon Type (for race bonus) | C23: Dagger | D23: Weapon specific race trait applied? | E23: =IFS( AND(C22="Goblin", C23="Dagger"), TRUE, AND(C22="Golem", C23="Colossal Sword"), TRUE, AND(C22="Golem", C23="Great Axe"), TRUE, AND(C22="Felynx", C23="Gauntlets"), TRUE, AND(C22="Vampire",C23="Straight Sword"), TRUE, TRUE, FALSE ) -> FALSE
B25: RUNE SLOTS
B26: Slot | C26: Stat 1 | D26: Stat 2
A27: =IF(ISNUMBER(SEARCH("Lethality",C27)),VALUE(MID(C27,FIND("+",C27)+1,LEN(C27)-FIND("+",C27)-1))/100,0)+IF(ISNUMBER(SEARCH("Lethality",D27)),VALUE(MID(D27,FIND("+",D27)+1,LEN(D27)-FIND("+",D27)-1))/100,0)+IF(ISNUMBER(SEARCH("Lethality",C28)),VALUE(MID(C28,FIND("+",C28)+1,LEN(C28)-FIND("+",C28)-1))/100,0)+IF(ISNUMBER(SEARCH("Lethality",D28)),VALUE(MID(D28,FIND("+",D28)+1,LEN(D28)-FIND("+",D28)-1))/100,0)+IF(ISNUMBER(SEARCH("Lethality",C29)),VALUE(MID(C29,FIND("+",C29)+1,LEN(C29)-FIND("+",C29)-1))/100,0)+IF(ISNUMBER(SEARCH("Lethality",D29)),VALUE(MID(D29,FIND("+",D29)+1,LEN(D29)-FIND("+",D29)-1))/100,0) -> 0 | B27: Rune 1 | C27: None | D27: None | E27: ← Select from drop down
A28: =IF(ISNUMBER(SEARCH("Crit Chance",C27)),VALUE(MID(C27,FIND("+",C27)+1,LEN(C27)-FIND("+",C27)-1))/100,0)+IF(ISNUMBER(SEARCH("Crit Chance",D27)),VALUE(MID(D27,FIND("+",D27)+1,LEN(D27)-FIND("+",D27)-1))/100,0)+IF(ISNUMBER(SEARCH("Crit Chance",C28)),VALUE(MID(C28,FIND("+",C28)+1,LEN(C28)-FIND("+",C28)-1))/100,0)+IF(ISNUMBER(SEARCH("Crit Chance",D28)),VALUE(MID(D28,FIND("+",D28)+1,LEN(D28)-FIND("+",D28)-1))/100,0)+IF(ISNUMBER(SEARCH("Crit Chance",C29)),VALUE(MID(C29,FIND("+",C29)+1,LEN(C29)-FIND("+",C29)-1))/100,0)+IF(ISNUMBER(SEARCH("Crit Chance",D29)),VALUE(MID(D29,FIND("+",D29)+1,LEN(D29)-FIND("+",D29)-1))/100,0) -> 0 | B28: Rune 2 | C28: None | D28: None | E28: ← Select from drop down
A29: =IF(ISNUMBER(SEARCH("Crit DMG",C27)),VALUE(MID(C27,FIND("+",C27)+1,LEN(C27)-FIND("+",C27)-1))/100,0)+IF(ISNUMBER(SEARCH("Crit DMG",D27)),VALUE(MID(D27,FIND("+",D27)+1,LEN(D27)-FIND("+",D27)-1))/100,0)+IF(ISNUMBER(SEARCH("Crit DMG",C28)),VALUE(MID(C28,FIND("+",C28)+1,LEN(C28)-FIND("+",C28)-1))/100,0)+IF(ISNUMBER(SEARCH("Crit DMG",D28)),VALUE(MID(D28,FIND("+",D28)+1,LEN(D28)-FIND("+",D28)-1))/100,0)+IF(ISNUMBER(SEARCH("Crit DMG",C29)),VALUE(MID(C29,FIND("+",C29)+1,LEN(C29)-FIND("+",C29)-1))/100,0)+IF(ISNUMBER(SEARCH("Crit DMG",D29)),VALUE(MID(D29,FIND("+",D29)+1,LEN(D29)-FIND("+",D29)-1))/100,0) -> 0 | B29: Rune 3 | C29: None | D29: None | E29: ← Select from drop down
A30: =IF(ISNUMBER(SEARCH("Atk Speed",C27)),VALUE(MID(C27,FIND("+",C27)+1,LEN(C27)-FIND("+",C27)-1))/100,0)+IF(ISNUMBER(SEARCH("Atk Speed",D27)),VALUE(MID(D27,FIND("+",D27)+1,LEN(D27)-FIND("+",D27)-1))/100,0)+IF(ISNUMBER(SEARCH("Atk Speed",C28)),VALUE(MID(C28,FIND("+",C28)+1,LEN(C28)-FIND("+",C28)-1))/100,0)+IF(ISNUMBER(SEARCH("Atk Speed",D28)),VALUE(MID(D28,FIND("+",D28)+1,LEN(D28)-FIND("+",D28)-1))/100,0)+IF(ISNUMBER(SEARCH("Atk Speed",C29)),VALUE(MID(C29,FIND("+",C29)+1,LEN(C29)-FIND("+",C29)-1))/100,0)+IF(ISNUMBER(SEARCH("Atk Speed",D29)),VALUE(MID(D29,FIND("+",D29)+1,LEN(D29)-FIND("+",D29)-1))/100,0) -> 0 | B30: Total | C30: =TEXT(A27*100,"0.0")&"% Leth +"&TEXT(A28*100,"0.0")&"% CC +"&TEXT(A29*100,"0.0")&"% CD +"&TEXT(A30*100,"0.0")&"% AS" -> 0.0% Leth +0.0% CC +0.0% CD +0.0% AS
A31: =IF(ISNUMBER(SEARCH("Atk Speed",C27)),VALUE(MID(C27,FIND("+",C27)+1,LEN(C27)-FIND("+",C27)-1))/100,0)+IF(ISNUMBER(SEARCH("Atk Speed",D27)),VALUE(MID(D27,FIND("+",D27)+1,LEN(D27)-FIND("+",D27)-1))/100,0)+IF(ISNUMBER(SEARCH("Atk Speed",C28)),VALUE(MID(C28,FIND("+",C28)+1,LEN(C28)-FIND("+",C28)-1))/100,0)+IF(ISNUMBER(SEARCH("Atk Speed",D28)),VALUE(MID(D28,FIND("+",D28)+1,LEN(D28)-FIND("+",D28)-1))/100,0)+IF(ISNUMBER(SEARCH("Atk Speed",C29)),VALUE(MID(C29,FIND("+",C29)+1,LEN(C29)-FIND("+",C29)-1))/100,0)+IF(ISNUMBER(SEARCH("Atk Speed",D29)),VALUE(MID(D29,FIND("+",D29)+1,LEN(D29)-FIND("+",D29)-1))/100,0) -> 0
A32: IFS(C6="Frost Fossil",IF(SUM($D$6:$D$9)=0,0,IF(D6/SUM($D$6:$D$9)<0.1,0,(1.75+(17.5-1.75)*MIN((D6/SUM($D$6:$D$9)-0.1)/0.2,1))/100)),C6="Crimsonite",IF(SUM($D$6:$D$9)=0,0,IF(D6/SUM($D$6:$D$9)<0.1,0,(2+(20-2)*MIN((D6/SUM($D$6:$D$9)-0.1)/0.2,1))/100)),C6="Sealed Curse",IF(SUM($D$6:$D$9)=0,0,IF(D6/SUM($D$6:$D$9)<0.1,0,(3+(30-3)*MIN((D6/SUM($D$6:$D$9)-0.1)/0.2,1))/100)),TRUE,0)+IFS(C7="Frost Fossil",IF(SUM($D$6:$D$9)=0,0,IF(D7/SUM($D$6:$D$9)<0.1,0,(1.75+(17.5-1.75)*MIN((D7/SUM($D$6:$D$9)-0.1)/0.2,1))/100)),C7="Crimsonite",IF(SUM($D$6:$D$9)=0,0,IF(D7/SUM($D$6:$D$9)<0.1,0,(2+(20-2)*MIN((D7/SUM($D$6:$D$9)-0.1)/0.2,1))/100)),C7="Sealed Curse",IF(SUM($D$6:$D$9)=0,0,IF(D7/SUM($D$6:$D$9)<0.1,0,(3+(30-3)*MIN((D7/SUM($D$6:$D$9)-0.1)/0.2,1))/100)),TRUE,0)+IFS(C8="Frost Fossil",IF(SUM($D$6:$D$9)=0,0,IF(D8/SUM($D$6:$D$9)<0.1,0,(1.75+(17.5-1.75)*MIN((D8/SUM($D$6:$D$9)-0.1)/0.2,1))/100)),C8="Crimsonite",IF(SUM($D$6:$D$9)=0,0,IF(D8/SUM($D$6:$D$9)<0.1,0,(2+(20-2)*MIN((D8/SUM($D$6:$D$9)-0.1)/0.2,1))/100)),C8="Sealed Curse",IF(SUM($D$6:$D$9)=0,0,IF(D8/SUM($D$6:$D$9)<0.1,0,(3+(30-3)*MIN((D8/SUM($D$6:$D$9)-0.1)/0.2,1))/100)),TRUE,0)+IFS(C9="Frost Fossil",IF(SUM($D$6:$D$9)=0,0,IF(D9/SUM($D$6:$D$9)<0.1,0,(1.75+(17.5-1.75)*MIN((D9/SUM($D$6:$D$9)-0.1)/0.2,1))/100)),C9="Crimsonite",IF(SUM($D$6:$D$9)=0,0,IF(D9/SUM($D$6:$D$9)<0.1,0,(2+(20-2)*MIN((D9/SUM($D$6:$D$9)-0.1)/0.2,1))/100)),C9="Sealed Curse",IF(SUM($D$6:$D$9)=0,0,IF(D9/SUM($D$6:$D$9)<0.1,0,(3+(30-3)*MIN((D9/SUM($D$6:$D$9)-0.1)/0.2,1))/100)),TRUE,0) | B32: RUNE ABILITIES
B33: Ability | C33: Fire | D33: Poison | E33: Blast
B34: Ability DMG (% of base weapon DMG) | C34: 0 | D34: 0 | E34: 0
B35: Ability Proc Chance % | C35: 0 | D35: 0 | E35: 0
B36: Time (seconds) | C36: 0 | D36: 0
B38: ORE TRAITS
B39: Trait / Bonus | C39: Value (input) | D39: Calculated | E39: DPS Contribution
B40: Stat Bonuses (from ore traits & race)
B41: Crit Chance armor bonus (if Yin Yang armor) | C41: 0 | D41: Auto-calculated from ores (all stack) | E41: =MIN(C41, 100%) -> 0
B42: Crit DMG armor bonus (if Yin Yang armor) | C42: 0 | E42: =MIN(C42, 100%) -> 0
B43: Lethality Bonus (if sealed curse, eye ore, frost fossil or kokorite armor) % | C43: 0 | E43: =MIN(C43, 150%) -> 0
...

Sheet _Weapon
B1: WeaponType | C1: WeaponName | D1: AttackSpeed | E1: AttackDamage | H1: Dagger | I1: Straight Sword | J1: Mace | K1: Gauntlet | L1: Axe | M1: Katana | N1: Great Sword | O1: Spear | P1: Great Axe | Q1: Colossal Sword
B2: Dagger | C2: Dagger | D2: 0.47 | E2: 4.3 | H2: Dagger | I2: Falchion | J2: Mace | K2: Ironhand | L2: Axe | M2: Uchigatana | N2: Crusader Sword | O2: Spear | P2: Double Battle Axe | Q2: Great Sword
B3: Dagger | C3: Falchion Knife | D3: 0.47 | E3: 4.3 | H3: Falchion Knife | I3: Gladius | J3: Spiked Mace | K3: Boxing Glove | L3: Battleaxe | M3: Tachi | N3: Long Sword | O3: Trident | P3: Scythe | Q3: Hammer
B4: Dagger | C4: Gladius Dagger | D4: 0.47 | E4: 4.3 | H4: Gladius Dagger | I4: Cutlass | J4: Winged Mace | K4: Relevator | L4: Curved Handle Axe | M4: Straight Edge Katana | N4: Dark Knight Greatsword | O4: Angelic Spear | P4: Greater Battle Axe | Q4: Skull Crusher
B5: Dagger | C5: Hook | D5: 0.52 | E5: 4.73 | H5: Hook | I5: Rapier | J5: Hammerhead Mace | K5: Savage Claws | L5: Spade Armed Axe | M5: Washimaru | N5: Anchored Greatsword | O5: Demonic Spear | P5: Wyvern Axe | Q5: Dragon Slayer
B6: Dagger | C6: Cultist Dagger | D6: 0.47 | E6: 5.25 | H6: Cultist Dagger | I6: Chaos | J6: Grave Maker | K6: DKG | L6: Ornate short axe | M6: Kurokiba-gatana | N6: Zweihander | O6: Knight Spear | P6: Reaper | Q6: Comically Large Spoon
B7: Dagger | C7: Shark's Fang | D7: 0.36 | E7: 3.87 | H7: Shark's Fang | I7: Hell Slayer | J7: Kanabo | M7: Juto Katana | O7: Compass Spear | P7: Executioner's Greataxe | Q7: Excalibur
B8: Dagger | C8: Curved Dagger | D8: 0.41 | E8: 4.95 | H8: Curved Dagger | I8: Candy Cane | J8: Tetsubo | O8: Shakujo | P8: Anchored Straight Blade | Q8: Colossal Terrorblade
B9: Dagger | C9: Kunai | D9: 0.39 | E9: 3.87 | H9: Kunai | I9: Crystalized Broadsword | O9: Sodegarami | P9: Sun Great Axe | Q9: Colossal Gemblade
B10: Dagger | C10: Jitte | D10: 0.49 | E10: 4.95 | H10: Jitte | I10: Hook Blade | O10: Bo Staff | Q10: Otsuchi
B11: Dagger | C11: Damascus Dagger | D11: 0.47 | E11: 4.73 | H11: Damascus Dagger | I11: Hachiwari | O11: Naginata | Q11: Kinmon Kamagatana
B12: Straight Sword | C12: Falchion | D12: 0.7 | E12: 7.5 | I12: Chokuto | Q12: Sharktooth Odachi
B13: Straight Sword | C13: Gladius | D13: 0.74 | E13: 7.88 | I13: Dragon Blade
B14: Straight Sword | C14: Cutlass | D14: 0.48 | E14: 9.375
B15: Straight Sword | C15: Rapier | D15: 0.58 | E15: 7.5
B16: Straight Sword | C16: Chaos | D16: 0.7 | E16: 9.375
B17: Straight Sword | C17: Hell Slayer | D17: 0.7 | E17: 10.125
B18: Straight Sword | C18: Candy Cane | D18: 0.52 | E18: 7.5
B19: Straight Sword | C19: Crystalized Broadsword | D19: 0.74 | E19: 9.98
B20: Straight Sword | C20: Hook Blade | D20: 0.52 | E20: 8.25
B21: Straight Sword | C21: Hachiwari | D21: 0.7 | E21: 8.25
B22: Straight Sword | C22: Chokuto | D22: 0.64 | E22: 7.5
B23: Straight Sword | C23: Dragon Blade | D23: 0.7 | E23: 10.5
B24: Mace | C24: Mace | D24: 1.17 | E24: 6
B25: Mace | C25: Spiked Mace | D25: 1.17 | E25: 6.3
... B80: Colossal Sword | C80: Sharktooth Odachi | D80: 1.4 | E80: 27

Sheet _OptionsCrafter
A1: Weapon Variant | B1: Dagger | C1: Dagger | D1: Dagger | E1: Dagger | F1: Dagger | G1: Dagger | H1: Dagger | I1: Dagger | J1: Dagger | K1: Dagger | L1: Dagger
A2: Weapon Type | B2: Dagger | C2: Falchion Knife | D2: Gladius Dagger | E2: Hook | F2: Cultist Dagger | G2: Shark's Fang | H2: Curved Dagger | I2: Kunai | J2: Jitte | K2: Damascus Dagger | L2: Tanto
A3: Attackspeed | B3: 0.47 | C3: 0.47 | D3: 0.47 | E3: 0.52 | F3: 0.47 | G3: 0.36 | H3: 0.41 | I3: 0.39 | J3: 0.49 | K3: 0.47 | L3: 0.39
A4: Attackdamage | B4: 4.3 | C4: 4.3 | D4: 4.3 | E4: 4.73 | F4: 5.25 | G4: 3.87 | H4: 4.95 | I4: 3.87 | J4: 4.95 | K4: 4.73 | L4: 4.95
A6: Weapon Variant | B6: Straight Sword | C6: Straight Sword | D6: Straight Sword | E6: Straight Sword | F6: Straight Sword | G6: Straight Sword | H6: Straight Sword | I6: Straight Sword | J6: Straight Sword | K6: Straight Sword | L6: Straight Sword | M6: Straight Sword
A7: Weapon Type | B7: Falchion | C7: Gladius | D7: Cutlass | E7: Rapier | F7: Chaos | G7: Hell Slayer | H7: Candy Cane | I7: Crystalized Broadsword | J7: Hook Blade | K7: Hachiwari | L7: Chokuto | M7: Dragon Blade
A8: Attackspeed | B8: 0.7 | C8: 0.74 | D8: 0.48 | E8: 0.58 | F8: 0.7 | G8: 0.7 | H8: 0.52 | I8: 0.74 | J8: 0.52 | K8: 0.7 | L8: 0.64 | M8: 0.7
A9: Attackdamage | B9: 7.5 | C9: 7.88 | D9: 9.375 | E9: 7.5 | F9: 9.375 | G9: 10.125 | H9: 7.5 | I9: 9.98 | J9: 8.25 | K9: 8.25 | L9: 7.5 | M9: 10.5
A11: Weapon Variant | B11: Mace | C11: Mace | D11: Mace | E11: Mace | F11: Mace | G11: Mace | H11: Mace
A12: Weapon Type | B12: Mace | C12: Spiked Mace | D12: Winged Mace | E12: Hammerhead Mace | F12: Grave Maker | G12: Kanabo | H12: Tetsubo
A13: Attackspeed | B13: 1.17 | C13: 1.17 | D13: 1.17 | E13: 1.17 | F13: 1.17 | G13: 1.3 | H13: 1.11
A14: Attackdamage | B14: 6 | C14: 6.3 | D14: 6.6 | E14: 6.9 | F14: 7.8 | G14: 7.2 | H14: 6.72
A16: Weapon Variant | B16: Gauntlet | C16: Gauntlet | D16: Gauntlet | E16: Gauntlet | F16: Gauntlet
A17: Weapon Type | B17: Ironhand | C17: Boxing Glove | D17: Relevator | E17: Savage Claws | F17: DKG
A18: Attackspeed | B18: 0.55 | C18: 0.63 | D18: 0.74 | E18: 0.51 | F18: 0.51
A19: Attackdamage | B19: 7.6 | C19: 8 | D19: 9.6 | E19: 8 | F19: 10
A21: Weapon Variant | B21: Axe | C21: Axe | D21: Axe | E21: Axe | F21: Axe
A22: Weapon Type | B22: Axe | C22: Battleaxe | D22: Curved Handle Axe | E22: Spade Armed Axe | F22: Ornate short axe
A23: Attackspeed | B23: 0.88 | C23: 0.88 | D23: 0.88 | E23: 0.88 | F23: 0.88
A24: Attackdamage | B24: 7 | C24: 7.35 | D24: 7.7 | E24: 8.05 | F24: 8.4
A26: Weapon Variant | B26: Katana | C26: Katana | D26: Katana | E26: Katana | F26: Katana | G26: Katana
A27: Weapon Type | B27: Uchigatana | C27: Tachi | D27: Straight Edge Katana | E27: Washimaru | F27: Kurokiba-gatana | G27: Juto Katana
A28: Attackspeed | B28: 0.69 | C28: 0.73 | D28: 0.69 | E28: 0.58 | F28: 0.63 | G28: 0.69
A29: Attackdamage | B29: 8.5 | C29: 8.925 | D29: 9.35 | E29: 10.2 | F29: 9.35 | G29: 8.5
A31: Weapon Variant | B31: Great Sword | C31: Great Sword | D31: Great Sword | E31: Great Sword | F31: Great Sword
A32: Weapon Type | B32: Crusader Sword | C32: Long Sword | D32: Dark Knight Greatsword | E32: Anchored Greatsword | F32: Zweihander
A33: Attackspeed | B33: 1.2 | C33: 1.33. | D33: 1.33 | E33: 1.09 | F33: 1.26
A34: Attackdamage | B34: 12 | C34: 12 | D34: 15 | E34: 13.8 | F34: 14.4
A36: Weapon Variant | B36: Spear | C36: Spear | D36: Spear | E36: Spear | F36: Spear | G36: Spear | H36: Spear | I36: Spear | J36: Spear | K36: Spear
A37: Weapon Type | B37: Spear | C37: Trident | D37: Angelic Spear | E37: Demonic Spear | F37: Knight Spear | G37: Compass Spear | H37: Shakujo | I37: Sodegarami | J37: Bo Staff | K37: Naginata
A38: Attackspeed | B38: 0.73 | C38: 0.73 | D38: 0.66 | E38: 0.79 | F38: 0.6 | G38: 0.76 | H38: 0.73 | I38: 0.66 | J38: 0.66 | K38: 0.73
A39: Attackdamage | B39: 7.5 | C39: 7.5 | D39: 9.75 | E39: 9 | F39: 7.5 | G39: 10.5 | H39: 7.5 | I39: 10.13 | J39: 10.5 | K39: 10.88
A41: Weapon Variant | B41: Great Axe | C41: Great Axe | D41: Great Axe | E41: Great Axe | F41: Great Axe | G41: Great Axe | H41: Great Axe | I41: Great Axe
A42: Weapon Type | B42: Double Battle Axe | C42: Scythe | D42: Greater Battle Axe | E42: Wyvern Axe | F42: Reaper | G42: Executioner's Greataxe | H42: Anchored Straight Blade | I42: Sun Great Axe
A43: Attackspeed | B43: 1.7 | C43: 1.54 | D43: 1.62 | E43: 1.47 | F43: 1.54 | G43: 1.7 | H43: 1.62 | I43: 1.35
A44: Attackdamage | B44: 15.75 | C44: 14.25 | D44: 17.25 | E44: 18.75 | F44: 14.25 | G44: 19.5 | H44: 18 | I44: 19.5
A46: Weapon Variant | B46: Colossal Sword | C46: Colossal Sword | D46: Colossal Sword | E46: Colossal Sword | F46: Colossal Sword | G46: Colossal Sword | H46: Colossal Sword | I46: Colossal Sword | J46: Colossal Sword | K46: Colossal Sword | L46: Colossal Sword
A47: Weapon Type | B47: Great Sword | C47: Hammer | D47: Skull Crusher | E47: Dragon Slayer | F47: Comically Large Spoon | G47: Excalibur | H47: Colossal Terrorblade | I47: Colossal Gemblade | J47: Otsuchi | K47: Kinmon Kamagatana | L47: Sharktooth Odachi
A48: Attackspeed | B48: 1.4 | C48: 1.56 | D48: 1.75 | E48: 1.4 | F48: 1.4 | G48: 1.4 | H48: 1.28 | I48: 1.4 | J48: 1.56 | K48: 1.4 | L48: 1.4
A49: Attackdamage | B49: 20 | C49: 22 | D49: 24 | E49: 22 | F49: 18 | G49: 26 | H49: 22 | I49: 23 | J49: 25 | K49: 23.4 | L49: 27
...

Sheet _Options
A1: None | B1: Human | C1: Physical Damage +5% | E1: Race \ Trait | F1: Physical Damage +5% | G1: Physical Damage +10% | H1: Physical Damage +12% | I1: Physical Damage +20% | J1: Physical Damage +20% (Gauntlets Only) | K1: Physical Damage +30% (below 50% HP) | L1: Attack Speed +15% (Heavy Weapons Only) | M1: Attack Speed +10% | N1: Attack speed +10% (Daggers only) | O1: Attack Speed +20% (Gauntlets Only) | P1: Attack Speed +20% | Q1: Fire Damage +20% | R1: 50% chance to deal 30% Physical Damage on-hit | S1: 40% chance to burn enemies for 30% weapon damage/s for 3 seconds | T1: 10% Damage Boost (Straight Swords Only) | U1: Deals 10% weapon damage/s during combat
A2: Crit Chance +5% | B2: Elf | C2: Physical Damage +10% | E2: Human | F2: 0 | G2: 0 | H2: 0 | I2: 0 | J2: 0 | K2: 0 | L2: 0 | M2: 0 | N2: 0 | O2: 0 | P2: 0 | Q2: 0 | R2: 0 | S2: 0 | T2: 0 | U2: 0
A3: Crit Chance +6% | B3: Zombie | C3: Physical Damage +12% | E3: Elf | F3: 0 | G3: 0 | H3: 0 | I3: 0 | J3: 0 | K3: 0 | L3: 0 | M3: 0 | N3: 0 | O3: 0 | P3: 0 | Q3: 0 | R3: 0 | S3: 0 | T3: 0 | U3: 0
A4: Crit Chance +7% | B4: Goblin | C4: Physical Damage +20% | E4: Zombie | F4: 0 | G4: 0 | H4: 0 | I4: 0 | J4: 0 | K4: 0 | L4: 0 | M4: 0 | N4: 0 | O4: 0 | P4: 0 | Q4: 0 | R4: 0 | S4: 0 | T4: 0 | U4: 0
A5: Crit Chance +8% | B5: Undead | C5: Physical Damage +20% with Gauntlets | E5: Goblin | F5: 0 | G5: 0 | H5: 0 | I5: 0 | J5: 0 | K5: 0 | L5: 0 | M5: 0 | N5: TRUE | O5: 0 | P5: 0 | Q5: 0 | R5: 0 | S5: 0 | T5: 0 | U5: 0
A6: Crit Chance +9% | B6: Orc | C6: Physical Damage +30% (below 50% HP) | E6: Undead | F6: 0 | G6: 0 | H6: 0 | I6: 0 | J6: 0 | K6: 0 | L6: 0 | M6: 0 | N6: 0 | O6: 0 | P6: 0 | Q6: 0 | R6: 0 | S6: 0 | T6: 0 | U6: 0
A7: Crit Chance +10% | B7: Dwarf | C7: Attack Speed +10% | E7: Orc | F7: 0 | G7: TRUE | H7: 0 | I7: 0 | J7: 0 | K7: 0 | L7: 0 | M7: 0 | N7: 0 | O7: 0 | P7: 0 | Q7: 0 | R7: 0 | S7: 0 | T7: 0 | U7: 0
A8: Crit Chance +11% | B8: Shadow | C8: Attack Speed +15% for heavy weapons | E8: Dwarf | F8: 0 | G8: 0 | H8: 0 | I8: 0 | J8: 0 | K8: 0 | L8: 0 | M8: 0 | N8: 0 | O8: 0 | P8: 0 | Q8: 0 | R8: 0 | S8: 0 | T8: 0 | U8: 0
A9: Crit Chance +12% | B9: Vampire | C9: Attack Speed +10% with Daggers | E9: Shadow | F9: TRUE | G9: 0 | H9: 0 | I9: 0 | J9: 0 | K9: 0 | L9: 0 | M9: TRUE | N9: 0 | O9: 0 | P9: 0 | Q9: 0 | R9: 0 | S9: 0 | T9: 0 | U9: 0
A10: Crit Chance +13% | B10: Minotaur | C10: Attack Speed +20% with Gauntlets | E10: Vampire | F10: 0 | G10: 0 | H10: 0 | I10: 0 | J10: 0 | K10: 0 | L10: 0 | M10: 0 | N10: 0 | O10: 0 | P10: 0 | Q10: 0 | R10: 0 | S10: 0 | T10: TRUE | U10: 0
A11: Crit Chance +14% | B11: Dragonborn | C11: Attack Speed +20% | E11: Minotaur | F11: 0 | G11: 0 | H11: 0 | I11: 0 | J11: 0 | K11: TRUE | L11: 0 | M11: 0 | N11: 0 | O11: 0 | P11: 0 | Q11: 0 | R11: 0 | S11: 0 | T11: 0 | U11: 0
A12: Crit Chance +15% | B12: Golem | C12: Fire Damage +20% | E12: Dragonborn | F12: 0 | G12: 0 | H12: TRUE | I12: 0 | J12: 0 | K12: 0 | L12: 0 | M12: 0 | N12: 0 | O12: 0 | P12: 0 | Q12: 0 | R12: 0 | S12: TRUE | T12: 0 | U12: 0
A13: Crit DMG +5% | B13: Felynx | C13: 50% chance to deal 30% Physical Damage on-hit | E13: Golem | F13: 0 | G13: 0 | H13: 0 | I13: 0 | J13: 0 | K13: 0 | L13: TRUE | M13: 0 | N13: 0 | O13: 0 | P13: 0 | Q13: 0 | R13: 0 | S13: 0 | T13: 0 | U13: 0
A14: Crit DMG +6% | B14: Angel | C14: 40% chance to burn enemies for 30% weapon damage/s for 3 seconds" | E14: Felynx | F14: 0 | G14: 0 | H14: 0 | I14: 0 | J14: TRUE | K14: 0 | L14: 0 | M14: 0 | N14: 0 | O14: TRUE | P14: 0 | Q14: 0 | R14: 0 | S14: 0 | T14: 0 | U14: 0
A15: Crit DMG +7% | B15: Demon | C15: Physical Damage +10% (Straight Sword Only) | E15: Angel | F15: 0 | G15: 0 | H15: 0 | I15: 0 | J15: 0 | K15: 0 | L15: 0 | M15: 0 | N15: 0 | O15: 0 | P15: 0 | Q15: 0 | R15: TRUE | S15: 0 | T15: 0 | U15: 0
A16: Crit DMG +8% | B16: Archangel | C16: Deals 10% weapon damage/s during combat | E16: Demon | F16: 0 | G16: 0 | H16: 0 | I16: TRUE | J16: 0 | K16: 0 | L16: 0 | M16: 0 | N16: 0 | O16: 0 | P16: TRUE | Q16: TRUE | R16: 0 | S16: 0 | T16: 0 | U16: TRUE
A17: Crit DMG +9% | E17: Archangel | F17: 0 | G17: 0 | H17: 0 | I17: TRUE | J17: 0 | K17: 0 | L17: 0 | M17: 0 | N17: 0 | O17: 0 | P17: TRUE | Q17: 0 | R17: 0 | S17: 0 | T17: 0 | U17: 0
A18: Crit DMG +10%
A19: Crit DMG +11%
A20: Crit DMG +12%
A21: Crit DMG +13%
A22: Crit DMG +14%
A23: Crit DMG +15%
A24: Atk Speed +5%
A25: Atk Speed +6%
A26: Atk Speed +7%
A27: Atk Speed +8%
A28: Atk Speed +9%
A29: Atk Speed +10%
... A48: Lethality +15%

Sheet IGNORE REF CALC
A1: Dagger | B1: Straight Sword | C1: Mace | D1: Gauntlet | E1: Axe | F1: Katana | G1: Great Sword | H1: Spear | I1: Great Axe | J1: Colossal Sword | L1: Active List
A2: Dagger | B2: Falchion | C2: Mace | D2: Ironhand | E2: Axe | F2: Uchigatana | G2: Crusader Sword | H2: Spear | I2: Double Battle Axe | J2: Great Sword | L2: {=INDEX($A$2:$J$13,,MATCH('DPS Calculator'!$C$12,$A$1:$J$1,0))} -> Spear
A3: Falchion Knife | B3: Gladius | C3: Spiked Mace | D3: Boxing Glove | E3: Battleaxe | F3: Tachi | G3: Long Sword | H3: Trident | I3: Scythe | J3: Hammer | L3: Trident
A4: Gladius Dagger | B4: Cutlass | C4: Winged Mace | D4: Relevator | E4: Curved Handle Axe | F4: Straight Edge Katana | G4: Dark Knight Greatsword | H4: Angelic Spear | I4: Greater Battle Axe | J4: Skull Crusher | L4: Angelic Spear
A5: Hook | B5: Rapier | C5: Hammerhead Mace | D5: Savage Claws | E5: Spade Armed Axe | F5: Washimaru | G5: Anchored Greatsword | H5: Demonic Spear | I5: Wyvern Axe | J5: Dragon Slayer | L5: Demonic Spear
A6: Cultist Dagger | B6: Chaos | C6: Grave Maker | D6: DKG | E6: Ornate short axe | F6: Kurokiba-gatana | G6: Zweihander | H6: Knight Spear | I6: Reaper | J6: Comically Large Spoon | L6: Knight Spear
A7: Shark's Fang | B7: Hell Slayer | C7: Kanabo | F7: Juto Katana | H7: Compass Spear | I7: Executioner's Greataxe | J7: Excalibur | L7: Compass Spear
A8: Curved Dagger | B8: Candy Cane | C8: Tetsubo | H8: Shakujo | I8: Anchored Straight Blade | J8: Colossal Terrorblade | L8: Shakujo
A9: Kunai | B9: Crystalized Broadsword | H9: Sodegarami | I9: Sun Great Axe | J9: Colossal Gemblade | L9: Sodegarami
A10: Jitte | B10: Hook Blade | H10: Bo Staff | J10: Otsuchi | L10: Bo Staff
A11: Damascus Dagger | B11: Hachiwari | H11: Naginata | J11: Kinmon Kamagatana | L11: Naginata
B12: Chokuto | J12: Sharktooth Odachi
B13: Dragon Blade
